Workbook

Sheet תעריפים
A2: רשות שדות התעופה
A4: דוח ביצוע שעות עבודה ינואר 2025
A5: אהובה אליה-הנדסת תנועה ותחבורה | B5: כתובת :האורן 44 רמת ישי ת.ד. 1051 | C5: פלאפון: 054-9983894 | E5: עוסק מורשה: 057085250
A6: לקוח | B6: תדם | C6: 45658 | E6: רשות שדות התעופה
A7: המתכנן | B7: אהובה אליה | E7: מספר ח-ן: 01012501
A10: תאריך | B10: יום השבוע | C10: סהכ שעות עבודה | D10: מיקום | E10: נושא העבודה
A11: 45658 | B11: ד | C11: 6 | D11: רש"ת | E11: ועדת תנועה 12-24
A12: 45659 | B12: ה | C12: 4 | D12: משרד
A13: 45665 | B13: ד | C13: 6 | D13: רש"ת
A14: 45666 | B14: ה | C14: 4 | D14: משרד
A15: 45670 | B15: ב | C15: 5 | D15: רש"ת
A16: 45673 | B16: ה | C16: 5 | D16: משרד
A17: 45679 | B17: ד | C17: 6 | D17: רש"ת
A18: 45680 | B18: ה | C18: 5 | D18: משרד
A19: 45684 | B19: ב | C19: 6 | D19: רש"ת
A20: 45686 | B20: ד | C20: 7 | D20: משרד | E20: ועדת תנועה 01-25
A21: 45687 | B21: ה | C21: 6 | D21: משרד
A22: סה"כ | C22: =SUM(C11:C21) -> 60 | D22: =+'דצמבר 2024'!E14 -> 1774 | E22: =D22-C22 -> 1714
A25: סה"כ שעות עבודה | C25: 85
A26: מחיר לשעת עבודה | C26: 225
A27: סה"כ לחשבון | C27: =C26*C25 -> 19125
A28: מע"מ 18% | C28: =+C27*18/100 -> 3442.5
A29: סה"כ לחשבון | C29: =C28+C27 -> 22567.5
A31: הצהרת העובד - הנני מצהיר בזה, כי כל הפרטים לגבי ביצוע שעות העבודה בדו"ח זה הינם נכונים ותואמים את הרישומים של משרדנו
A32: חתימה | G32: תאריך | H32: 45688
A33: שם העובד | D33: אהובה אליה
A34: אישור המתכנן | G34: אישור העיריה
A35: לגבי סווג רמת התעריף ומספר שעות העובד : | E35: שם
A36: שם | E36: תפקיד
A37: חתימה | E37: חתימה | H37: תאריך
A38: במידה והמתכנן מעסיק יותר מעובד אחד עליו להגיש גם דף ריכוז לכל העובדים

Sheet דצמבר 2024
A2: רשות שדות התעופה
A4: דוח ביצוע שעות עבודה דצמבר 2024
A5: אהובה אליה-הנדסת תנועה ותחבורה | B5: כתובת :האורן 44 רמת ישי ת.ד. 1051 | C5: פלאפון: 054-9983894 | E5: עוסק מורשה: 057085250
A6: לקוח | B6: תדם | C6: 45627 | E6: רשות שדות התעופה
A7: המתכנן | B7: אהובה אליה | E7: מספר ח-ן: 01122401
A10: תאריך | B10: יום השבוע | C10: סהכ שעות עבודה | D10: מיקום | E10: נושא העבודה
A11: 46013 | B11: א | C11: 8 | D11: רש"ת | E11: ועדת תנועה 12-24
A12: 46016 | B12: ד | C12: 10 | D12: משרד
A13: 46017 | B13: ה | C13: 8 | D13: משרד
A14: סה"כ | C14: =SUM(C11:C13) -> 26 | D14: 1800 | E14: =D14-C14 -> 1774
A17: סה"כ שעות עבודה | C17: 26
A18: מחיר לשעת עבודה
A19: סה"כ לחשבון
A20: מע"מ 18%
A21: סה"כ לחשבון | C21: =C20+C19 -> 0
A23: הצהרת העובד - הנני מצהיר בזה, כי כל הפרטים לגבי ביצוע שעות העבודה בדו"ח זה הינם נכונים ותואמים את הרישומים של משרדנו
A24: חתימה | G24: תאריך | H24: 45656
A25: שם העובד | D25: אהובה אליה
A26: אישור המתכנן | G26: אישור העיריה
A27: לגבי סווג רמת התעריף ומספר שעות העובד : | E27: שם
A28: שם | E28: תפקיד
A29: חתימה | E29: חתימה | H29: תאריך
A30: במידה והמתכנן מעסיק יותר מעובד אחד עליו להגיש גם דף ריכוז לכל העובדים

Sheet ינואר 2025
A2: רשות שדות התעופה
A4: דוח ביצוע שעות עבודה ינואר 2025
A5: אהובה אליה-הנדסת תנועה ותחבורה | B5: כתובת :האורן 44 רמת ישי ת.ד. 1051 | C5: פלאפון: 054-9983894 | E5: עוסק מורשה: 057085250
A6: לקוח | B6: תדם | C6: 45658 | E6: רשות שדות התעופה
A7: המתכנן | B7: אהובה אליה | E7: מספר ח-ן: 01012501
A10: תאריך | B10: יום השבוע | C10: סהכ שעות עבודה | D10: מיקום | E10: נושא העבודה
A11: 45658 | B11: ד | C11: 6 | D11: רש"ת | E11: ועדת תנועה 12-24
A12: 45659 | B12: ה | C12: 4 | D12: משרד
A13: 45665 | B13: ד | C13: 6 | D13: רש"ת
A14: 45666 | B14: ה | C14: 4 | D14: משרד
A15: 45670 | B15: ב | C15: 5 | D15: רש"ת
A16: 45673 | B16: ה | C16: 5 | D16: משרד
A17: 45679 | B17: ד | C17: 6 | D17: רש"ת
A18: 45680 | B18: ה | C18: 5 | D18: משרד
A19: 45684 | B19: ב | C19: 6 | D19: רש"ת
A20: 45686 | B20: ד | C20: 7 | D20: משרד | E20: ועדת תנועה 01-25
A21: 45687 | B21: ה | C21: 6 | D21: משרד
A22: סה"כ | C22: =SUM(C11:C21) -> 60 | D22: =+'דצמבר 2024'!E14 -> 1774 | E22: =D22-C22 -> 1714
A25: סה"כ שעות עבודה | C25: 60
A26: מחיר לשעת עבודה
A27: סה"כ לחשבון
A28: מע"מ 18%
A29: סה"כ לחשבון | C29: =C28+C27 -> 0
A31: הצהרת העובד - הנני מצהיר בזה, כי כל הפרטים לגבי ביצוע שעות העבודה בדו"ח זה הינם נכונים ותואמים את הרישומים של משרדנו
A32: חתימה | G32: תאריך | H32: 45688
A33: שם העובד | D33: אהובה אליה
A34: אישור המתכנן | G34: אישור העיריה
A35: לגבי סווג רמת התעריף ומספר שעות העובד : | E35: שם
A36: שם | E36: תפקיד
A37: חתימה | E37: חתימה | H37: תאריך
A38: במידה והמתכנן מעסיק יותר מעובד אחד עליו להגיש גם דף ריכוז לכל העובדים

Sheet פברואר 2025
A2: רשות שדות התעופה
A4: דוח ביצוע שעות עבודה פברואר 2025
A5: אהובה אליה-הנדסת תנועה ותחבורה | B5: כתובת :האורן 44 רמת ישי ת.ד. 1051 | C5: פלאפון: 054-9983894 | E5: עוסק מורשה: 057085250
A6: לקוח | B6: תדם | C6: 45689 | E6: רשות שדות התעופה
A7: המתכנן | B7: אהובה אליה | E7: מספר ח-ן: 01022501
A10: תאריך | B10: יום השבוע | C10: סהכ שעות עבודה | D10: מיקום | E10: נושא העבודה | K10: טיפול כולל - הכנה+ טיפול בכל נושא הארכיב החתימות וההפצה
A11: 45691 | B11: ב | C11: 2 | D11: רש"ת | E11: בקרה והפצת פרוטוקול ועדת תנועה 01-25
C12: 3 | D12: רש"ת | E12: ארגון והכנת חומר לועדת תנועה 02-25
A13: 45694 | B13: ב | C13: 3 | D13: משרד | E13: היכרות ודיון בנושא שינוי תוואי דרך עוקפת ל-K4
A14: 45698 | B14: ב | C14: 8 | D14: רש"ת | E14: הכנת חומר לועדת תנועה 02-25
A15: 45699 | B15: ג | C15: 2 | D15: משרד | E15: דיון עם שרלי אמיר בנושאים לועדת התנועה 02-25
B16: ג | C16: 4 | D16: משרד | E16: הכנת החומר לועדת תנועה 02-25
A17: 45700 | B17: ד | C17: 3 | D17: משרד | E17: היכרות ודיון בנושא גדר החייץ שלבי ביצוע
A18: 45701 | B18: ה | C18: 2 | D18: משרד | E18: לדיון בנושאים שונים ועדת תנועה 02-25 עם חן פרידמן
C19: 8 | E19: בקרת איכות והכנת חומר לועדת תנועה 02-25
A20: 45704 | B20: א | C20: 1 | D20: רש"ת | E20: ועדת תנועה 02-25
C21: 4 | D21: רש"ת | E21: בקרה הכנה וטיפול בכל הקשור לפרוטוקול לאחר ועדת תנועה 02-25
C22: 4 | D22: משרד
A23: 45705 | B23: ב | C23: 8 | D23: משרד
A24: 45706 | B24: ג | C24: 8 | D24: משרד
A25: 45707 | B25: ד | C25: 6 | D25: משרד
A26: 45708 | B26: ה | C26: 10 | D26: משרד | E26: תכנון תנועה -במפלס ת.ציבורית טרמינל 3-הסדרי תמרור לחניית מוניות ונכים
A27: 45711 | B27: א | C27: 10 | D27: משרד
A28: 45713 | B28: ה | C28: 3 | D28: משרד | E28: בקרה ודיון בנושא גדר החייץ שלבי ביצוע
A29: 45714 | B29: א | C29: 6 | D29: משרד | E29: קבלה חומרים מעודכנים לאחר בקרת איכות וסגירת הפרוטוקול ועדת התנועה 02-25
A30: 45715 | B30: ה | C30: 2 | D30: משרד | E30: בקרה ודיון בנושא יב"ר עם עירד
A31: סה"כ | C31: =SUM(C11:C30) -> 97 | D31: =+'ינואר 2025'!E22 -> 1714 | E31: =D31-C31 -> 1617
A34: סה"כ שעות עבודה | D34: 97
A35: מחיר לשעת עבודה
A36: סה"כ לחשבון
A37: מע"מ 18%
A38: סה"כ לחשבון | D38: =D37+D36 -> 0
A40: הצהרת העובד - הנני מצהיר בזה, כי כל הפרטים לגבי ביצוע שעות העבודה בדו"ח זה הינם נכונים ותואמים את הרישומים של משרדנו
A41: חתימה | G41: תאריך | H41: 45688
A42: שם העובד | D42: אהובה אליה
A43: אישור המתכנן | G43: אישור העיריה
A44: לגבי סווג רמת התעריף ומספר שעות העובד : | E44: שם
A45: שם | E45: תפקיד
A46: חתימה | E46: חתימה | H46: תאריך

Sheet מרץ 2025 
A2: רשות שדות התעופה
A4: דוח ביצוע שעות עבודה מרץ 2025
A5: אהובה אליה-הנדסת תנועה ותחבורה | B5: כתובת :האורן 44 רמת ישי ת.ד. 1051 | C5: פלאפון: 054-9983894 | E5: עוסק מורשה: 057085250
A6: לקוח | B6: תדם | C6: 45717 | E6: רשות שדות התעופה
A7: המתכנן | B7: אהובה אליה | E7: מספר ח-ן: 01032501
A10: תאריך | B10: יום השבוע | C10: סהכ שעות עבודה | D10: מיקום | E10: נושא העבודה | K10: טיפול כולל - הכנה+ טיפול בכל נושא הארכיב החתימות וההפצה
A11: 45718 | B11: א | C11: 3 | D11: רש"ת | E11: היכרות עם פרוייקט מכ"מ 38
C12: 3.5 | D12: רש"ת | E12: הכנת נושאי דיון לועדת תנועה 03/25
A13: 45719 | B13: ב | C13: 3 | D13: משרד | E13: פרויקט יב"ר -פגישה עם שגיב וארזה
C14: 3.5 | D14: משרד | E14: המשך היכרות ודיון בפרויקט יב"ר לקראת ועדת תנועה 03/25
A15: 45720 | B15: ג | C15: 5 | D15: משרד | E15: טרמינל 1 - הוספת מקומות נגישים - קבלת תוכניות מיזם דיון ושיבוץ בועדת התנועה
C16: 5 | D16: רש"ת | E16: טרמינל 3 - חניות למסורבים ובטחון - קבלת תוכניות מיזם דיון ושיבוץ בועדת התנועה
A17: 45722 | B17: ה | C17: 5 | D17: משרד | E17: טרמינל 3 - הרשאת גישה למסלול הדרומי - קבלת תוכניות מיזם דיון ושיבוץ בועדת התנועה
C18: 5 | D18: משרד | E18: המשך הכנת נושאים לסדר יום ועדת תנועה 03/25
A19: 45725 | B19: א | C19: 3 | D19: רש"ת | E19: הכנה היכרות ודיון בנושא מכ"מ נייד לקראת ועדת תנועה 03/25
C20: 3 | E20: הפצה ותיוק ועדת תנועה 02/25
A21: 45726 | B21: ב | C21: 2 | D21: משרד | E21: הכנה היכרות ודיון פרויקט קידוחי תחנת דס"ל
A22: 45728 | B22: ד | C22: 4 | D22: משרד | E22: היכרות ודיון בנושא גדר חייץ שלב א לקראת ועדת תנועה 03/25
C23: 3 | D23: משרד | E23: הכנה היכרות ודיון בנושא מכ"מ נייד 38 לקראת ועדת תנועה 03/25
C24: 3 | D24: משרד | E24: הכנה היכרות ודיון בנושא העתקת כלורינטור חלופי טרמינל 3 לקראת ועדת תנועה 03/25
A25: 45729 | B25: ה | C25: 7 | D25: משרד | E25: הכנת סדר יום סופי כולל בקרת איכות לועדת תנועה 03/25 והפצתו
A26: 45732 | B26: א | C26: 2 | D26: רש"ת | E26: הכנה ודיון בועדת תנועה 03/25
C27: 5 | D27: רש"ת | E27: בקרת איכות ארגון וסידור הקבצים על פי נושאים לאחר ועדת התנועה 03/25
A28: 45736 | B28: ה | C28: 8 | D28: משרד | E28: הכנת פרוטוקול ואישור תוכן לאחר ועדת תנועה 03/25
A29: 45739 | B29: א | C29: 3 | D29: רש"ת | E29: הכנה וסיור בשטח פרוייקט גדר חייץ שלב א
C30: 3 | D30: רש"ת | E30: דיון נוסף בפרויקט הסדרי תנועה זמניים קידוחי תחנת דס"ל
A31: 45741 | B31: ג | C31: 5 | D31: משרד | E31: המשך הכנת פרוטוקול לחתימות +ארכוב+ טיפול בתוכניות לאישור - ועדת תנועה 03/25
A32: 45743 | B32: ה | C32: 5 | D32: משרד | E32: המשך הכנת פרוטוקול לחתימות +ארכוב+ טיפול בתוכניות לאישור - ועדת תנועה 03/25
C33: 2 | D33: משרד | E33: בקרה ודיון בפרויקט כלורינטור לאחר ועדת התנועה
A34: 45746 | B34: א | C34: 4 | D34: רש"ת | E34: דיון וסיור בשטח פרוייקט הסדרי תנועה זמניים קידוחי תחנת דס"ל
C35: 2 | D35: רש"ת | E35: שליחת פרוטוקול לחתימות ותוכניות לאישור - ועדת תנועה 03/25
A36: סה"כ | C36: =SUM(C11:C35) -> 97 | D36: =+'פברואר 2025'!E31 -> 1617 | E36: =D36-C36 -> 1520
A39: סה"כ שעות עבודה | D39: 97
A40: מחיר לשעת עבודה
A41: סה"כ לחשבון
A42: מע"מ 18%
A43: סה"כ לחשבון | D43: =D42+D41 -> 0
A45: הצהרת העובד - הנני מצהיר בזה, כי כל הפרטים לגבי ביצוע שעות העבודה בדו"ח זה הינם נכונים ותואמים את הרישומים של משרדנו
A46: חתימה | G46: תאריך | H46: 45752
A47: שם העובד | D47: אהובה אליה
...

Sheet אפריל 2025  
A2: רשות שדות התעופה
A4: דוח ביצוע שעות עבודה אפריל 2025
A5: אהובה אליה-הנדסת תנועה ותחבורה | B5: כתובת :האורן 44 רמת ישי ת.ד. 1051 | C5: פלאפון: 054-9983894 | E5: עוסק מורשה: 057085250
A6: לקוח | B6: תדם | C6: 45748 | E6: רשות שדות התעופה
A7: המתכנן | B7: אהובה אליה | E7: מספר ח-ן: 01042501
A10: תאריך | B10: יום השבוע | C10: סהכ שעות עבודה | D10: מיקום | E10: נושא העבודה | K10: טיפול כולל - הכנה+ טיפול בכל נושא הארכיב החתימות וההפצה
A11: 45749 | B11: ד | C11: 3 | D11: רש"ת | E11: איסוף וריכוז חומר רקע בנושא פרוייקט כביש 200
C12: 2 | D12: רש"ת | E12: ישיבה עם אדר' שירלי בנוגע למתן התייחסות רש"ת לפרויקט כביש 200.
A13: 45753 | B13: א | C13: 3 | D13: רש"ת | E13: הכנה היכרות וסיור בנושא הת"ז לביצוע עבודות ברחוב יעף -מפעלי מזון תמ"מ לקראת ועדת תנועה 04/25
C14: 2 | D14: רש"ת | E14: הכנה היכרות וסיור לבקשת מחלקת אכיפה להסדרת חניית מוניות במפלס ת.ציבורית טרמינל 3
A15: 45754 | B15: ב | C15: 3 | D15: משרד | E15: איסוף והכנת נושאים לסדר יום ועדת תנועה 04/25
C16: 3 | D16: משרד | E16: הכנה היכרות ודיון בנושא פסיפס מזרחי לקראת ועדת תנועה 04/25
C17: 2 | D17: משרד | E17: קבלת חומרים מעודכנים לאחר סיור ודיון חוזר בנושא תחנת דלק דס"ל לקראת ועדת תנועה 04/25
A18: 45755 | B18: ג | C18: 9 | D18: משרד | E18: תכנון תנועה -במפלס ת.ציבורית טרמינל 3-עדכון הסדרי חניה למוניות בקומה
A19: 45757 | B19: ה | C19: 10 | D19: משרד
A20: 45768 | B20: א | C20: 2 | D20: רש"ת | E20: הכנה היכרות ודיון בנושא תוכנית מפרצי אוטובוס E2+E3 לקראת ועדת תנועה 04/25
C21: 5 | D21: רש"ת | E21: המשך איסוף והכנת נושאים לסדר יום ועדת תנועה 04/25
A22: 45769 | B22: ג | C22: 2 | D22: משרד | E22: דיון והצגת התכנון תנועה למזמין וקבלת אישורו לקראת ועדת התנועה 04/25
C23: 3 | D23: משרד | E23: הכנה היכרות ודיון בנושא תוכנית מפרצי אוטובוס E2+E3 לקראת ועדת תנועה 04/25 - שי עמית והדס הראל
A24: 45770 | B24: ד | C24: 2 | D24: משרד | E24: קבלת חומרים מעודכנים לאחר סיור ובקרת איכות בנושא רחוב יעף-הת"ז לביצוע קווי ניקוז לקראת ועדת תנועה 04/25
C25: 3 | E25: הכנה היכרות ודיון בנושא נספח תנועה וחניה לחניון בין מבנה תחזוקה למבנה מוקד לקראת ועדת תנועה 04/25
A26: 45771 | B26: ה | C26: 3 | D26: משרד | E26: הצגה היכרות +דיון בפרוייקט גדר חייץ שלב ב
C27: 2 | D27: משרד | E27: המשך הצגה ודיון עם המתכננים בנושא נספח תנועה וחניה לחניון בין מבנה תחזוקה למבנה מוקד לקראת ועדת תנועה 04/25
C28: 2 | D28: משרד | E28: הכנת סדר יום סופי כולל בקרת איכות לועדת תנועה 04/25 והפצתו
A29: 45774 | B29: א | C29: 1.5 | D29: משרד | E29: הכנה ודיון בועדת תנועה 04/25
C30: 3.5 | D30: משרד | E30: הכנת פרוטוקול ואישור תוכן לאחר ועדת תנועה 04/25
C31: 1 | D31: משרד | E31: ישיבה עם אדר' שירלי בנוגע למתן התייחסות לרש"ת לפרויקט כביש 200-דיון חוזר.
A32: 45775 | B32: ב | C32: 6 | D32: משרד | E32: המשך הכנת פרוטוקול לחתימות +ארכוב+ טיפול בתוכניות לאישור - ועדת תנועה 04/25
A33: סה"כ | C33: =SUM(C11:C32) -> 73 | D33: =+'מרץ 2025 '!E36 -> 1520 | E33: =D33-C33 -> 1447
A36: סה"כ שעות עבודה | D36: 73
A37: מחיר לשעת עבודה
A38: סה"כ לחשבון
A39: מע"מ 18%
A40: סה"כ לחשבון | D40: =D39+D38 -> 0
A42: הצהרת העובד - הנני מצהיר בזה, כי כל הפרטים לגבי ביצוע שעות העבודה בדו"ח זה הינם נכונים ותואמים את הרישומים של משרדנו
A43: חתימה | G43: תאריך | H43: 45752
A44: שם העובד | D44: אהובה אליה
A45: אישור המתכנן | G45: אישור העיריה
A46: לגבי סווג רמת התעריף ומספר שעות העובד : | E46: שם
A47: שם | E47: תפקיד
...

Sheet מאי 2025 
A2: רשות שדות התעופה
A4: דוח ביצוע שעות עבודה מאי 2025
A5: אהובה אליה-הנדסת תנועה ותחבורה | B5: כתובת :האורן 44 רמת ישי ת.ד. 1051 | C5: פלאפון: 054-9983894 | E5: עוסק מורשה: 057085250
A6: לקוח | B6: תדם | C6: 45778 | E6: רשות שדות התעופה
A7: המתכנן | B7: אהובה אליה | E7: מספר ח-ן: 01052501
A10: תאריך | B10: יום השבוע | C10: סהכ שעות עבודה | D10: מיקום | E10: נושא העבודה | K10: טיפול כולל - הכנה+ טיפול בכל נושא הארכיב החתימות וההפצה
A11: 45788 | B11: א | C11: 2 | D11: רש"ת | E11: הכנה היכרות ודיון ראשוני בנושא דדי שחר טרמינל 3 נתב"ג-הסדרי תנועה מבנה תפעול לקראת ועדת תנועה 05/25
C12: 2 | D12: רש"ת | E12: היכרות וסיור בטרמינל 3 MLR2- הסדרת תמרור וסימון לטובת תאי חניה לטובת חטיבת הנדסה +טעינה חשמלית לקראת ועדת תנועה 05/25
C13: 2 | D13: רש"ת | E13: הפצה ותיוק ועדת תנועה 03/25
A14: 45790 | B14: ג | C14: 3 | D14: משרד | E14: קבלת חומרים מעודכנים ודיון חוזר עם המתכנן ומנהל הפרויקט בנושא דדי שחר טרמינל 3-הסדרי תנועה מבנה תפעול לקראת ועדת תנועה 05/25
C15: 6 | D15: רש"ת | E15: איסוף והכנת נושאים לסדר יום ועדת תנועה 05/25
A16: 45792 | B16: ה | C16: 10 | D16: משרד | E16: תכנון תנועה -במפלס ת.ציבורית טרמינל 3-הסדרי תנועה וחניה לטובת חטיבת הנדסה +רכבי טעינה חשמלית
A17: 45793 | B17: ו | C17: 5 | D17: משרד
A18: 45795 | B18: א | C18: 3 | D18: משרד | E18: הכנה היכרות ראשונית בנושא שער ברוש לקראת ועדת תנועה 05/25
C19: 2 | D19: משרד | E19: דיון והצגת התכנון תנועה למזמין וקבלת אישורו לקראת ועדת התנועה 05/25
A20: 45796 | B20: ב | C20: 6 | D20: רש"ת | E20: המשך קבלת חומרים מעודכנים בנושאים השונים וביצוע בקרת איכות לקראת ועדת תנועה 05/25
C21: 3 | D21: רש"ת | E21: הכנה היכרות סיור ודיון בנושא גדר החיץ - שלב ב מקטע א חתכים 0-400(שלב ב) -הת"ז לביצוע גדר החיץ לקראת ועדת תנועה 05/25
A22: 45799 | B22: ה | C22: 2 | D22: משרד | E22: קבלת חומרים מעודכנים דיון חוזר ובקרת איכות בנושא שער ברוש לקראת ועדת תנועה 05/25
C23: 2 | D23: משרד | E23: קבלת חומרים מעודכנים דיון חוזר ובקרת איכות בנושא גדר חייץ לקראת ועדת תנועה 05/25
C24: 5 | D24: משרד | E24: הכנת סדר יום סופי כולל בקרת איכות והפצתו + הכנת מצגת לקראת ועדת תנועה 05/25
A25: 45802 | B25: א | C25: 5 | D25: משרד | E25: המשך הכנת מצגת כולל בקרת איכות לקראת ועדת תנועה 05/25
A26: 45803 | B26: ב | C26: 2 | D26: משרד | E26: הכנה ודיון בועדת תנועה 05/25
C27: 1 | D27: משרד | E27: ישיבה עם אדר' שירלי בנוגע למתן התייחסות לרש"ת לפרויקט כביש 200-דיון חוזר.
C28: 3 | D28: משרד | E28: הכנת פרוטוקול ואישור תוכן לאחר ועדת תנועה 05/25
A29: 45804 | B29: ג | C29: 9 | D29: משרד | E29: המשך הכנת פרוטוקול לחתימות +ארכוב+ טיפול בתוכניות לאישור - ועדת תנועה 05/25
A30: סה"כ | C30: =SUM(C11:C29) -> 73 | D30: =+'אפריל 2025 '!E33 -> 1447 | E30: =D30-C30 -> 1374
A33: סה"כ שעות עבודה | D33: 73
A34: מחיר לשעת עבודה
A35: סה"כ לחשבון
A36: מע"מ 18%
A37: סה"כ לחשבון | D37: =D36+D35 -> 0
A39: הצהרת העובד - הנני מצהיר בזה, כי כל הפרטים לגבי ביצוע שעות העבודה בדו"ח זה הינם נכונים ותואמים את הרישומים של משרדנו
A40: חתימה | G40: תאריך | H40: 45807
A41: שם העובד | D41: אהובה אליה
A42: אישור המתכנן | G42: אישור העיריה
A43: לגבי סווג רמת התעריף ומספר שעות העובד : | E43: שם
A44: שם | E44: תפקיד
A45: חתימה | E45: חתימה | H45: תאריך

Sheet יוני 2025  
A2: רשות שדות התעופה
A4: דוח ביצוע שעות עבודה יוני 2025
A5: אהובה אליה-הנדסת תנועה ותחבורה | B5: כתובת :האורן 44 רמת ישי ת.ד. 1051 | C5: פלאפון: 054-9983894 | E5: עוסק מורשה: 057085250
A6: לקוח | B6: תדם | C6: 45809 | E6: רשות שדות התעופה
A7: המתכנן | B7: אהובה אליה | E7: מספר ח-ן: 01062501
A10: תאריך | B10: יום השבוע | C10: סהכ שעות עבודה | D10: מיקום | E10: נושא העבודה | K10: טיפול כולל - הכנה+ טיפול בכל נושא הארכיב החתימות וההפצה
A11: 45813 | B11: ה | C11: 2 | D11: רש"ת | E11: הכנה היכרות ראשונית -חניון מצדה
A12: 45816 | B12: א | C12: 5 | D12: רש"ת | E12: הכנה היכרות סיור וחוות דעת - תחנת שאטל נוספת חניון 22
C13: 1 | D13: רש"ת | E13: תיוק ועדת תנועה 04/25
A14: 45818 | B14: ג | C14: 3 | D14: משרד | E14: הכנה היכרות ראשונית בנושא אגס קטן
A15: 45789 | B15: ה | C15: 6 | D15: משרד | E15: קבלת חומרים ראשונים בנושאים השונים לקראת ועדת תנועה 07/25
A16: 45827 | B16: ה | C16: 3 | D16: משרד | E16: הכנה היכרות ראשונית בנושא דוח 7- מסמכי עקרונות ותיאומים-אבנים קטנות בתחבורה
C17: 2 | D17: משרד | E17: התייחסות בנושא דוח 7- מסמכי עקרונות ותיאומים-אבנים קטנות בתחבורה- פגישה הכנה עם שירלי
A18: 45830 | B18: א | C18: 2 | D18: משרד | E18: דיון בנושא דוח 7- מסמכי עקרונות ותיאומים-אבנים קטנות בתחבורה-פגישה עם המתכננים
A19: 45833 | B19: ד | C19: 2 | D19: משרד | E19: הכנה היכרות לבקשת מחלקת אכיפה להסדרת סימון ותמרור למניעת חניות אופנועים
C20: 6 | D20: משרד | E20: תכנון תנועה -במפלס G טרמינל 3-הסדרת סימון ותמרור לטובת מניעת חניית אופנועים
A21: 45834 | B21: ה | C21: 10 | D21: משרד
A22: 45837 | B22: א | C22: 3 | D22: משרד | E22: הפצה בקרה +רישות בטבלאות אקסל +תיוק ועדת תנועה 05/25
A23: 45838 | B23: ב | C23: 3 | D23: משרד | E23: הכנה היכרות ודיון ראשוני בנושא פודקורט נתב"ג-הסדרי תנועה זמניים לקראת ועדת תנועה 07/25
A24: סה"כ | C24: =SUM(C11:C23) -> 48 | D24: =+'מאי 2025 '!E30 -> 1374 | E24: =D24-C24 -> 1326
A27: סה"כ שעות עבודה | D27: 48
A28: מחיר לשעת עבודה
A29: סה"כ לחשבון
A30: מע"מ 18%
A31: סה"כ לחשבון | D31: =D30+D29 -> 0
A33: הצהרת העובד - הנני מצהיר בזה, כי כל הפרטים לגבי ביצוע שעות העבודה בדו"ח זה הינם נכונים ותואמים את הרישומים של משרדנו
A34: חתימה | G34: תאריך | H34: 45838
A35: שם העובד | D35: אהובה אליה
A36: אישור המתכנן | G36: אישור העיריה
A37: לגבי סווג רמת התעריף ומספר שעות העובד : | E37: שם
A38: שם | E38: תפקיד
A39: חתימה | E39: חתימה | H39: תאריך

Sheet יולי 2025  
A2: רשות שדות התעופה
A4: דוח ביצוע שעות עבודה יולי 2025
A5: אהובה אליה-הנדסת תנועה ותחבורה | B5: כתובת :האורן 44 רמת ישי ת.ד. 1051 | C5: פלאפון: 054-9983894 | E5: עוסק מורשה: 057085250
A6: לקוח | B6: תדם | C6: 45839 | E6: רשות שדות התעופה
A7: המתכנן | B7: אהובה אליה | E7: מספר ח-ן: 01072501
A10: תאריך | B10: יום השבוע | C10: סהכ שעות עבודה | D10: מיקום | E10: נושא העבודה | K10: טיפול כולל - הכנה+ טיפול בכל נושא הארכיב החתימות וההפצה
A11: 45840 | B11: ד | C11: 2 | D11: רש"ת | E11: דיון וסיור בשטח האוירי בשטח בנושא: פודקורט - הסדרי תנועה זמניים
C12: 2 | D12: רש"ת | E12: הכנה וסיור -חניון מצדה
C13: 3 | D13: רש"ת | E13: איסוף ראשוני והכנת הנושאים לסדר יום ועדת תנועה 07/25
A14: 45844 | B14: א | C14: 2 | D14: רש"ת | E14: דיון וסיור בשטח בנושא: הסדרי תנועה כיכר אל-על
C15: 2 | D15: רש"ת | E15: סיור בשטח בנושא: גדר חיץ שלב ב קטע ג- הסדרי תנועה זמניים
C16: 3 | D16: רש"ת | E16: מסוף נתב"ג - עדכון גבולות רשות תמרור נת"י- הכנה + הצגת הפרויקט
A17: 45845 | B17: ב | C17: 2 | D17: משרד | E17: דיון והצגת תוכניות בנושא גדר החיץ - שלב ב מקטע שלישי חתכים 240-600 -הת"ז לביצוע גדר החיץ לקראת ועדת תנועה 07/25
C18: 2 | D18: משרד | E18: נתב"ג תשתיות קרקעיות -פ"ע יועצים פנימית בנושא דוח 7- אבנים קטנות בתחבורה
C19: 1 | D19: משרד | E19: דיון והצגת תכנון התנועה מפלס G טרמינל 3 למזמין וקבלת אישורו לקראת ועדת התנועה 07/25
A20: 45846 | B20: ג | C20: 9 | D20: משרד | E20: תכנון תנועה -טרמינל 3 MLR3-הסדרת סימון ותמרור לטובת העלאה והורדת נוסעים ללא המתנה כולל נכים
A21: 45848 | B21: ה | C21: 7 | D21: משרד
A22: 45851 | B22: א | C22: 2 | D22: רש"ת | E22: פגישה עם אורית חנון - בנושא ארכוב
C23: 1 | D23: רש"ת | E23: דיון והצגת תכנון התנועה מפלס G טרמינל 3 למזמין וקבלת אישורו לקראת ועדת התנועה 07/25
C24: 3 | D24: רש"ת | E24: פגישה להצגת בקשות לתכנון תנועה וסיור בשטח עם מנהל טרמינל 1-חיים אלימלך+ניצן זוהר
A25: 45853 | B25: ג | C25: 3 | D25: משרד | E25: הכנה היכרות ראשונית ודיון בנושא פאל 5-אזור מגדל הפיקוח לקראת ועדת תנועה 06/25
C26: 3 | D26: משרד | E26: הכנת פרוטוקול לחתימות +ארכוב+ טיפול בתוכניות לאישור והפצתו במייל - ועדת תנועה 06/25
C27: 4 | D27: משרד | E27: המשך איסוף והכנת הנושאים לסדר יום ועדת תנועה 07/25
A28: 45855 | B28: ה | C28: 2 | D28: משרד | E28: איסוף והכנת נושאים לסדר יום ועדת תנועה 06/25 והפצתו לכל חברי הועדה במייל
C29: 3 | D29: משרד | E29: דיון והצגת תוכניות חניון אל-על מגרש הכדורגל -עדכון הסדרי התנועה לקראת ועדת תנועה 07/25
A30: 45858 | B30: א | C30: 1 | D30: רש"ת | E30: דיון והצגת התייחסות למסוף נתב"ג עם ארזה ושירלי
C31: 1 | D31: רש"ת | E31: תיוק לאחר ועדת תנועה 06/25
C32: 5 | D32: רש"ת | E32: קבלת חומרים מעודכנים ובקרת איכות לנושאים השונים+ הכנה ראשונית של המצגת לקראת ועדת תנועה 07/25
A33: 45859 | B33: ב | C33: 7 | D33: משרד | E33: מסוף נתב"ג - הכנת חוות דעת יועץ תחבורה
C34: 2 | D34: משרד | E34: הכנה היכרות ראשונית ודיון בנושא הסדרת גישה לשער חירום חוות המיכלים פז (כיכר פ"ת-לוד) שער מזרח לקראת ועדת תנועה 07/25
A35: 45862 | B35: ה | C35: 8 | D35: משרד | E35: ביצוע בקרת איכות לתוכניות הסופיות +הכנת סדר יום סופי והפצתו + המשך הכנת המצגת לקראת ועדת התנועה 07/25
A36: 45865 | B36: א | C36: 2 | D36: רש"ת | E36: הכנה ודיון בועדת תנועה 07/25
C37: 3 | D37: רש"ת | E37: סיור ודיון -הסדרת גישה לשער חירום חוות המיכלים פז (כיכר פ"ת-לוד) שער מזרח לאחר ועדת תנועה 07/25 +
E38: סיור ודיון בנושא רמזור מבצע דני עקב תאונה
A39: 45866 | B39: ב | C39: 1 | D39: משרד | E39: פ"ע פנימית עם ליאור בנוגע למתן התייחסות רש"ת לפרויקט כביש 200
A40: 45867 | B40: ג | C40: 1 | D40: משרד | E40: פ"ע פנימית עם ארזה ושירלי- הכנה לפורום נתב"ג
C41: 2 | D41: משרד | E41: הכנה + דיון בנושא אגס קטן
A42: 45868 | B42: ד | C42: 2 | D42: משרד | E42: פורום נתב"ג
A43: 45869 | B43: ה | C43: 6 | D43: משרד | E43: הכנת פרוטוקול ואישור תוכן לאחר ועדת תנועה 07/25
A44: סה"כ | C44: =SUM(C11:C43) -> 97 | D44: =+'יוני 2025 '!E24 -> 1326 | E44: =D44-C44 -> 1229
...

Sheet אוג 2025 
A2: רשות שדות התעופה
A4: דוח ביצוע שעות עבודה אוג 2025
A5: אהובה אליה-הנדסת תנועה ותחבורה | B5: כתובת :האורן 44 רמת ישי ת.ד. 1051 | C5: פלאפון: 054-9983894 | E5: עוסק מורשה: 057085250
A6: לקוח | B6: תדם | C6: 45870 | E6: רשות שדות התעופה
A7: המתכנן | B7: אהובה אליה | E7: מספר ח-ן: 01082501
A10: תאריך | B10: יום השבוע | C10: סהכ שעות עבודה | D10: מיקום | E10: נושא העבודה | K10: טיפול כולל - הכנה+ טיפול בכל נושא הארכיב החתימות וההפצה
A11: 45872 | B11: א | C11: 6 | D11: רש"ת | E11: הכנת פרוטוקול לחתימות - ועדת תנועה 07/25
C12: 1 | D12: רש"ת | E12: שוטף אגפי
C13: 1 | D13: רש"ת | E13: חניון 15- היכרות ראשונית עם פרויקט חניון 15
A14: 45876 | B14: ה | C14: 5 | D14: משרד | E14: המשך הכנת פרוטוקול לחתימות + טיפול בתוכניות לאישור ושליחה לארכוב - ועדת תנועה 07/25
C15: 4 | D15: משרד | E15: חניון 15- קבלת חומר מעודכן מאדרכלים המשך בחינה והיכרות עם פרויקט חניון 15
A16: 45879 | B16: א | C16: 6 | D16: רש"ת | E16: איסוף והכנת נושאים לסדר יום ועדת תנועה 08/25
C17: 2 | D17: רש"ת | E17: הכנה והיכרות ראשונית בנושא XREY- לקראת ועדת תנועה 08/25
A18: 45880 | B18: ב | C18: 2 | D18: משרד | E18: חניון 15 - דיון והצגת תכנון התנועה ע"י המתכנן
C19: 1 | D19: משרד | E19: סיכום דיון בנושא הסדרת גישה לשער חירום חוות המיכלים פז (כיכר פ"ת-לוד) שער מזרח
A20: 45881 | B20: ג | C20: 2 | D20: משרד | E20: הכנה והיכרות ראשונית בנושא מיכלי סולר- לקראת ועדת תנועה 08/25
C21: 2 | D21: משרד | E21: חניון 15 - ביצוע בקרת איכות לתוכנית הסופית ואישורה
A22: 45883 | B22: ה | C22: 9 | D22: משרד | E22: הכנת חוות דעת יועץ תחבורה בנוגע לכביש 200- התייחסות לחלופה המוצעת
A23: 45887 | B23: ב | C23: 5 | D23: רש"ת | E23: בקרת איכות לתוכניות לקראת סגירת הפרוטוקול לאחר קבלת ארכוב ושליחה לחתימות- ועדת תנועה 07/25
C24: 1 | D24: רש"ת | E24: פגישה עם אורית חנון בנוגע לארכיב
C25: 1 | D25: רש"ת | E25: הכנה היכרות ראשונית בנושאים הנוגעים לטרמינל 1-לקראת ועדת תנועה 08/25
A26: 45890 | B26: ה | C26: 2 | D26: משרד | E26: דיון והצגת תוכניות כולל בקרת איכות בנושא מיכלי סולר- לקראת ועדת תנועה 08/25
C27: 1 | D27: משרד | E27: עדכון קבצי אקסל עם הפרויקטים ועדה 07/25
C28: 3 | D28: משרד | E28: טיפול ומסירת פרוטולים+תוכניות לבקשת התובעת רשותית ואגף האכיפה
A29: 45894 | B29: ב | C29: 2 | D29: משרד | E29: דיון והצגת התוכניות הסופיות בנושא חניון למוניות טרמינל 1 - לקראת ועדת תנועה 08/25
C30: 2 | D30: משרד | E30: דיון והצגת התוכניות הסופיות בנושא חניות להעלאה והורדה בחזית טרמינל 1 - לקראת ועדת תנועה 08/25
C31: 4 | D31: משרד | E31: הכנה היכרות ראשונית בנושא תכנון מסוף חיפה חלופות
A32: 45896 | B32: ד | C32: 2 | D32: משרד | E32: שדה תעופה חיפה - מגרש החניה בחיפה- הצגת חלופות עם תדם ומנהל הפרוקיט
C33: 2 | D33: משרד | E33: קבלת תוכניות תת"ל והמשך לימוד היכרות ובקרת תוכניות בנושא תכנון מגרש חניה בשדה התעופה חיפה
A34: 45897 | B34: ה | C34: 1 | D34: משרד | E34: שדה תעופה חיפה - מגרש החניה בחיפה- בחינת החלופות - שוטף עם ארזה + מנהל הפרויקט
C35: 3 | D35: משרד | E35: היכרות לימוד ודיון כולל תוכניות סופיות גדר החיץ (אגס קטן)עם מנהל הפרויקט בכר
C36: 5 | D36: משרד | E36: ביצוע בקרת איכות לתוכניות הסופיות +הכנת סדר יום סופי והפצתו לקראת ועדת התנועה 08/25
A37: 45900 | B37: א | C37: 5 | D37: משרד | E37: המשך ביצוע בקרת איכות לתוכניות הסופיות + הכנת המצגת לקראת ועדת התנועה 08/25
A38: סה"כ | C38: =SUM(C11:C37) -> 80 | D38: =+'יולי 2025 '!E44 -> 1229 | E38: =D38-C38 -> 1149
A41: סה"כ שעות עבודה | D41: 80
A42: מחיר לשעת עבודה
A43: סה"כ לחשבון
A44: מע"מ 18%
A45: סה"כ לחשבון | D45: =D44+D43 -> 0
A47: הצהרת העובד - הנני מצהיר בזה, כי כל הפרטים לגבי ביצוע שעות העבודה בדו"ח זה הינם נכונים ותואמים את הרישומים של משרדנו
...

Sheet ספט 2025  
A2: רשות שדות התעופה
A4: דוח ביצוע שעות עבודה ספט 2025
A5: אהובה אליה-הנדסת תנועה ותחבורה | B5: כתובת :האורן 44 רמת ישי ת.ד. 1051 | C5: פלאפון: 054-9983894 | E5: עוסק מורשה: 057085250
A6: לקוח | B6: תדם | C6: 45901 | E6: רשות שדות התעופה
A7: המתכנן | B7: אהובה אליה | E7: מספר ח-ן: 01092501
A10: תאריך | B10: יום השבוע | C10: סהכ שעות עבודה | D10: מיקום | E10: נושא העבודה | K10: טיפול כולל - הכנה+ טיפול בכל נושא הארכיב החתימות וההפצה
A11: 45904 | B11: ה | C11: 4 | D11: משרד | E11: סגירת סדר יום והפצתו + המשך הכנת המצגת לקראת ועדת התנועה 08/25
C12: 2 | D12: משרד | E12: דיון והצגת תוכניות כולל בקרת איכות בנושא XREY- לקראת ועדת תנועה 08/25
A13: 45907 | B13: א | C13: 2 | D13: רש"ת | E13: הכנה ודיון בועדת תנועה 08/25
C14: 1 | D14: רש"ת | E14: פ"ע פנימית עם ארזה ושירלי- שוטף
C15: 1 | D15: רש"ת | E15: פ"ע בנושא ארכוב -עם מחלקת ארכוב+ארזה
C16: 3.5 | D16: רש"ת | E16: הכנת פרוטוקול - ועדת תנועה 08/25
A17: 45914 | B17: א | C17: 6 | D17: רש"ת | E17: המשך הכנת הפרוטוקול ובקשה לקבלת תוכניות מעודכנות - ועדת תנועה 08/25
C18: 1 | D18: רש"ת | E18: פ"ע פנימית עם ארזה ושירלי- שוטף
C19: 2 | D19: רש"ת | E19: מעברי חירום נתב"ג - בקשה מצד המשטרה להסדרת מעברי חירום בנתב"ג
A20: 45915 | B20: ג | C20: 1 | D20: משרד | E20: דיון בנושא שדה תעופה חיפה -תכנון מגרש החניה - הצגת החלופות
A21: 45917 | B21: ד | C21: 3 | D21: משרד | E21: הכנה היכרות ראשונית בנושא בנין המשטרה החדש-לקראת ועדת תנועה 11/25
A22: 45921 | B22: א | C22: 3.5 | D22: רש"ת | E22: הכנה היכרות ראשונית בנושא מחלף נתב"ג מערב - הסדרי תנועה זמניים שלב A1 לקראת ועדת תנועה 09/25
C23: 1 | D23: רש"ת | E23: חוק חופש המידע - בקשה לאיתור פרוטוקולים ותוכניות מול עו"ד נטלי בן
C24: 1 | D24: רש"ת | E24: ישיבת אגף תכנון
A25: 45922 | B25: ב | C25: 2 | D25: משרד | E25: קבלת תוכניות ודיון בנושא מחלף נתב"ג מערב - הסדרי תנועה זמניים שלב A1 לקראת ועדת תנועה 09/25
A26: 45925 | B26: ה | C26: 4 | D26: משרד | E26: ביצוע בקרת איכות לתוכנית +הכנת סדר יום והפצתו במייל לקראת ועדת התנועה 09/25
C27: 3 | D27: משרד | E27: הכנת פרוטוקול לחתימות + טיפול בתוכניות לאישור ושליחה לארכוב - ועדת תנועה 09/25
A28: 45928 | B28: א | C28: 4 | D28: רש"ת | E28: הכנה המשך היכרות עם מכלי הסולר ברחבי נתב"ג לטובת היתרים- לקראת ועדת תנועה 11/25
C29: 3.5 | D29: רש"ת | E29: הכנה היכרות ראשונית בנושא מסוף בגין - הסדרי תנועה זמניים-לקראת ועדת תנועה 11/25
A30: 45929 | B30: ב | C30: 4 | D30: משרד | E30: טיפול ומסירת פרוטולים+תוכניות לבקשת חוק חופש המידע
C31: 1 | D31: משרד | E31: פ"ע פנימית עם ארזה ושירלי- שוטף
A32: 45930 | B32: ג | C32: 7.5 | D32: משרד | E32: בקרת איכות לתוכניות לקראת סגירת הפרוטוקול לאחר קבלת ארכוב ושליחה לחתימות- ועדת תנועה 08/25
A33: סה"כ | C33: =SUM(C11:C32) -> 61 | D33: =+'אוג 2025 '!E38 -> 1149 | E33: =D33-C33 -> 1088
A36: סה"כ שעות עבודה | D36: 61
A37: מחיר לשעת עבודה
A38: סה"כ לחשבון
A39: מע"מ 18%
A40: סה"כ לחשבון | D40: =D39+D38 -> 0
A42: הצהרת העובד - הנני מצהיר בזה, כי כל הפרטים לגבי ביצוע שעות העבודה בדו"ח זה הינם נכונים ותואמים את הרישומים של משרדנו
A43: חתימה | G43: תאריך | H43: 45930
A44: שם העובד | D44: אהובה אליה
A45: אישור המתכנן | G45: אישור העיריה
A46: לגבי סווג רמת התעריף ומספר שעות העובד : | E46: שם
A47: שם | E47: תפקיד
...

Sheet אוקטובר 2025   
A2: רשות שדות התעופה
A4: דוח ביצוע שעות עבודה אוקטובר 2025
A5: אהובה אליה-הנדסת תנועה ותחבורה | B5: כתובת :האורן 44 רמת ישי ת.ד. 1051 | C5: פלאפון: 054-9983894 | E5: עוסק מורשה: 057085250
A6: לקוח | B6: תדם | C6: 45931 | E6: רשות שדות התעופה
A7: המתכנן | B7: אהובה אליה | E7: מספר ח-ן: 01102501
A10: תאריך | B10: יום השבוע | C10: סהכ שעות עבודה | D10: מיקום | E10: נושא העבודה | K10: טיפול כולל - הכנה+ טיפול בכל נושא הארכיב החתימות וההפצה
A11: 45949 | B11: א | C11: 2 | D11: רש"ת | E11: דיון והצגת תוכניות כולל בקרת איכות בנושא מיכלי סולר- לקראת ועדת תנועה 11/25
C12: 3 | D12: רש"ת | E12: סיור בשטח בנוגע לנושא אכיפה אלקטרונית MLR קומה G -עם מחלקת אכיפה ועו"ד
C13: 3.5 | D13: רש"ת | E13: קבלת תוכניות מעודכנות ודיון עם המתכננים בנוגע לנספח התנועה בנין המשטרה החדש-לקראת ועדת תנועה 11/25
A14: 45953 | B14: ה | C14: 4 | D14: משרד | E14: הכנה היכרות ראשונית בנושא מחלף נתב"ג מערב - הסדרי תנועה זמניים שלב A0 - ניצבים-לקראת ועדת תנועה 10/25
C15: 1 | D15: רש"ת | E15: איסוף ראשוני והכנת הנושאים לסדר יום ועדת תנועה 10/25
A16: 45957 | B16: ב | C16: 3 | D16: רש"ת | E16: קבלת תוכניות מעודכנות וביצוע בקרת איכות בנוגע למכלי הסולר ברחבי נתב"ג לטובת היתרים- לקראת ועדת תנועה 11/25
C17: 2 | D17: רש"ת | E17: עדכון קבצי אקסל עם הפרויקטים לועדות התנועה 08/25
C18: 2 | D18: רש"ת | E18: תמרורי קנס מוגדל- בקשה לאיתור פרוטוקולים ותוכניות מול מחלקת אכיפה ועו"ד לימור טנצ'ר
A19: 45960 | B19: ה | C19: 4 | D19: משרד | E19: טיפול ומסירת פרוטולים+תוכניות לבקשת עו"ד טנצ'ר
C20: 4.5 | D20: משרד | E20: ביצוע בקרת איכות לתוכנית +הכנת סדר יום+ מצגת והפצתו במייל לחברי ועדת התנועה 10/25
C21: 1 | D21: משרד | E21: עדכון קבצי אקסל עם הפרויקטים ועדות התנועה 09/25
A22: סה"כ | C22: =SUM(C11:C21) -> 30 | D22: =+'ספט 2025 '!E33 -> 1088 | E22: =D22-C22 -> 1058
A25: סה"כ שעות עבודה | D25: 30
A26: מחיר לשעת עבודה
A27: סה"כ לחשבון
A28: מע"מ 18%
A29: סה"כ לחשבון | D29: =D28+D27 -> 0
A31: הצהרת העובד - הנני מצהיר בזה, כי כל הפרטים לגבי ביצוע שעות העבודה בדו"ח זה הינם נכונים ותואמים את הרישומים של משרדנו
A32: חתימה | G32: תאריך | H32: 45960
A33: שם העובד | D33: אהובה אליה
A34: אישור המתכנן | G34: אישור העיריה
A35: לגבי סווג רמת התעריף ומספר שעות העובד : | E35: שם
A36: שם | E36: תפקיד
A37: חתימה | E37: חתימה | H37: תאריך

Sheet נובמבר 2025  
A2: רשות שדות התעופה
A4: דוח ביצוע שעות עבודה נובמבר 2025
A5: אהובה אליה-הנדסת תנועה ותחבורה | B5: כתובת :האורן 44 רמת ישי ת.ד. 1051 | C5: פלאפון: 054-9983894 | E5: עוסק מורשה: 057085250
A6: לקוח | B6: תדם | C6: 45962 | E6: רשות שדות התעופה
A7: המתכנן | B7: אהובה אליה | E7: מספר ח-ן: 01112501
A10: תאריך | B10: יום השבוע | C10: סהכ שעות עבודה | D10: מיקום | E10: נושא העבודה | K10: טיפול כולל - הכנה+ טיפול בכל נושא הארכיב החתימות וההפצה
A11: 45963 | B11: א | C11: 2.5 | D11: רש"ת | E11: דיון והצגת תוכניות לאחר התייעצות ראשונית בנושא מסוף בגין - הסדרי תנועה זמניים-לקראת ועדת תנועה 11/25
C12: 2 | D12: רש"ת | E12: סיור בשטח -מחלף נתב"ג מערב - הסדרי תנועה זמניים שלב A0 - ניצבים-לקראת ועדת תנועה 10/25
C13: 2 | D13: רש"ת | E13: הכנת פרוטוקול לחתימות + טיפול בתוכניות לאישור ושליחה לארכוב - ועדת תנועה 10/25
A14: 45964 | B14: ב | C14: 3 | D14: משרד | E14: הכנה והיכרות ראשונית בנושא הסדרי תנועה היקפיים קיימים -נספח תנועה להסדרת היתר מגרש 2 לקראת ועדת תנועה 11/25
C15: 4 | D15: משרד | E15: איסוף והכנת הנושאים לסדר יום ועדת תנועה 11/25
C16: 1 | D16: משרד | E16: פגישת עבודה בנושא הסדרי תנועה היקפיים קיימים -נספח תנועה להסדרת היתר מגרש 2 לקראת ועדת תנועה 11/25
A17: 45967 | B17: ה | C17: 5 | D17: משרד | E17: דוח אמאב- אבנים קטנות בתחבורה- התייחסות נתב"ג -הכנת חוות דעת תחבורתית
A18: 45970 | B18: א | C18: 2 | D18: רש"ת | E18: תמרורי 433+ 439 בקשה לאיתור פרוטוקולים ותוכניות מול עו"ד נטלי בן - חוק חופש המידע
C19: 1 | D19: רש"ת | E19: שוטף עם ארזה ושירלי בנושא תמ"א
C20: 1 | D20: רש"ת | E20: ארכוב ועדות תנועה - שירלי הדס ואהובה
C21: 3.5 | D21: רש"ת | E21: הכנה והיכרות ראשונית בנושא הסדרי תנועה היקפיים קיימים -נספח תנועה להסדרת היתר מגרש 5 לקראת ועדת תנועה 11/25
A22: 45971 | B22: ב | C22: 2 | D22: משרד | E22: תמ"א נתב"ג- פרוגרמה תנועתית- דיון
A23: 45972 | B23: ג | C23: 2 | D23: רש"ת | E23: הכנה והיכרות ראשונית בנושא הסדרי תנועה היקפיים קיימים -נספח תנועה להסדרת היתר מגרש 7 לקראת ועדת תנועה 11/25
C24: 2 | D24: רש"ת | E24: המשך איסוף והכנת הנושאים לסדר יום ועדת תנועה 11/25
C25: 3 | D25: רש"ת | E25: פגישת עבודה נוספת בנושא הסדרי תנועה היקפיים קיימים -נספח תנועה להסדרת היתר למגרשים 5 ו-7 לקראת ועדת תנועה 11/25
A26: 45974 | B26: ה | C26: 3 | D26: משרד | E26: ביצוע בקרת איכות לתוכניות +הכנת סדר יום והפצתו לחברי הועדה לקראת ועדת התנועה 11/25
A27: 45972 | B27: ג | C27: 2 | D27: רש"ת | E27: הכנה והיכרות ראשונית בנושא הסדרי תנועה היקפיים קיימים -נספח תנועה להסדרת היתר מגרש 7 לקראת ועדת תנועה 11/25
C28: 2 | D28: רש"ת | E28: דיון חוזר והצגת תוכניות מעודכנות בנושא מסוף בגין - הסדרי תנועה זמניים-לקראת ועדת תנועה 11/25
C29: 3 | D29: רש"ת | E29: פגישת עבודה נוספת בנושא הסדרי תנועה היקפיים קיימים -נספח תנועה להסדרת היתר למגרשים 5 ו-7 לקראת ועדת תנועה 11/25
A30: 45974 | B30: ה | C30: 5 | D30: משרד | E30: קבלת תוכניות מעודכנות ביצוע בקרת איכות לתוכניות +הכנת הנושאים לסדר יום ועדת התנועה 11/25
C31: 1 | D31: משרד | E31: מחלף נתב"ג מערב -דיון והצגת הסדרי תנועה זמניים שלב A0 עם המתכנן
A32: 45979 | B32: ג | C32: 3 | D32: משרד | E32: ביצוע בקרת איכות לתוכנית +הכנת סדר יום סופי והפצתו ועדת תנועה 11/25
C33: 2 | D33: משרד | E33: דיון נוסף והצגת תוכניות מעודכנות כולל בקרת איכות בנושא מיכלי סולר- לקראת ועדת תנועה 11/25
C34: 2.5 | D34: משרד | E34: הכנה לפגישה תמ"א נתב"ג- פרוגרמה תנועתית
A35: 45980 | B35: ד | C35: 1.5 | D35: רש"ת | E35: מחלף נתב"ג מערב -סיור בשטח מאיר רחמים המשטרה ומנהל הפרויקטים
C36: 5 | D36: רש"ת | E36: המשך ביצוע בקרת איכות לתוכנית + הכנת מצגת לקראת ועדת התנועה 11/25
C37: 2 | D37: רש"ת | E37: תמ"א נתב"ג תשתיות קרקעיות צוות מלווה - פגישה
A38: 45984 | B38: א | C38: 2 | D38: רש"ת | E38: הכנה ודיון בועדת תנועה 11/25
C39: 1 | D39: רש"ת | E39: שוטף עם ארזה ושירלי בנושא שונים
C40: 6 | D40: רש"ת | E40: הכנת הפרוטוקול ובקשה לקבלת תוכניות מעודכנות - ועדת תנועה 11/25
A41: 45991 | B41: ה | C41: 3 | D41: רש"ת | E41: המשך הכנת הפרוטוקול ובקשה לקבלת תוכניות מעודכנות - ועדת תנועה 11/25
C42: 3 | D42: רש"ת | E42: מחלף נתב"ג מערב -קבלת תוכניות ולימוד החומר +דיון והצגת הסדרי תנועה זמניים שלב A3 ע"י המתכנן
A43: סה"כ | C43: =SUM(C11:C42) -> 83 | D43: =+'אוקטובר 2025 '!E22 -> 1058 | E43: =D43-C43 -> 975
A46: סה"כ שעות עבודה | D46: 83
...

Sheet דצמבר 2025 
A2: רשות שדות התעופה
A4: דוח ביצוע שעות עבודה דצמבר 2025
A5: אהובה אליה-הנדסת תנועה ותחבורה | B5: כתובת :האורן 44 רמת ישי ת.ד. 1051 | C5: פלאפון: 054-9983894 | E5: עוסק מורשה: 057085250
A6: לקוח | B6: תדם | C6: 45992 | E6: רשות שדות התעופה
A7: המתכנן | B7: אהובה אליה | E7: מספר ח-ן: 01122501
A10: תאריך | B10: יום השבוע | C10: סהכ שעות עבודה | D10: מיקום | E10: נושא העבודה | K10: טיפול כולל - הכנה+ טיפול בכל נושא הארכיב החתימות וההפצה
A11: 46360 | B11: ג | C11: 2 | D11: משרד | E11: חיפוש ומציאת שינוי גבולות רשות תמרור מסוף בגין
A12: 46363 | B12: א | C12: 1 | D12: רש"ת | E12: שוטף עם ארזה ושירלי בנושאים שונים
C13: 5 | D13: רש"ת | E13: הכנת הפרוטוקול כולל ביצוע בקרת איכות לחלק מהתוכניות וועדת תנועה 11/25
A14: 46365 | B14: ג | C14: 2 | D14: משרד | E14: דיון עם ניצן זוהר לבקשה לאיתור פרוטוקולים ותוכניות בנושא חופש המידע לבקשת לבקשת עו"ד נטלי בן עו"ד לימור טנצ'ר
A15: 46367 | B15: ה | C15: 3 | D15: משרד | E15: הכנה והיכרות ראשונית בנושא מחלף נתב"ג מערב שלב A1-הסדרי תנועה זמניים לקראת ועדת תנועה 01/26
C16: 5 | D16: משרד | E16: המשך הכנת פרוטוקול ובקשה לקבלת התוכניות מעודכנות לנושאים שונים בועדת תנועה 11/25
A17: 46370 | B17: א | C17: 4 | D17: רש"ת | E17: דיון עם מנהל הפרוקיט ירון מנשה +אדם הכהן רמ"ח ציוד ושינוע-אגף שינוע+מפקח שי עמירה - בנוגע לתוכניות סופיות וזמניות יב"ר לבקשת אדם הכהן
C18: 1 | D18: רש"ת | E18: הכנה ושוטף עם ארזה ושירלי בנושאים שונים
C19: 3 | D19: רש"ת | E19: דיון סיור והצגת הנושא ע"י המתכננים בנושא מחלף נתב"ג מערב שלב A1-הסדרי תנועה זמניים לקראת ועדת תנועה 01/26
A20: 46371 | B20: ב | C20: 1 | D20: משרד | E20: דיון והצגת הנושא לבקשת המשטרה בנוגע לנספח התנועה של המשטרה
C21: 8 | D21: משרד | E21: סגירת פרוטוקול קבלת תוכניות מעודכנות סופיות ושליחת תוכניות לארכוב ועדת תנועה 11/25
A22: 46374 | B22: ה | C22: 1 | D22: משרד | E22: שליחת תוכניות סופיות מעודכנות של ועדת תנועה 11/25 לאחר בקרת איכות למכון העתקות
A23: 46378 | B23: א | C23: 2 | D23: רש"ת | E23: לימוד והיכרות ראשונית בנושא תוכנית אב לשילוט עם שירלי
C24: 1 | D24: רש"ת | E24: שוטף עם ארזה ושירלי בנושאים שונים
C25: 3 | D25: רש"ת | E25: דיון נוסף והצגת הנושא מחלף נתב"ג מערב כולל ביצוע בקרת איכות לתוכניות הסדרי תנועה זמניים שלב A1
A26: 46379 | B26: ג | C26: 6 | D26: משרד | E26: UPS- לימוד ומתן חוות דעת בנושא צומת
C27: 3 | D27: משרד | E27: דיון נוסף לבקשת מירב שולר עקב אי התאמה בין נספח התנועה לתוכניות האדרכליות בנושא מכלי הסולר
A28: 46381 | B28: ה | C28: 3 | D28: משרד | E28: קבלת תוכניות ראשוניות- הכנה וביצוע בקרת איכות ראשונית בנושא גדר חייץ למקטע 4 שלב א- הסדרי תנועה זמניים
C29: 3 | D29: משרד | E29: קבלת תוכניות ראשוניות-הכנה וביצוע בקרת איכות ראשונית בנושא תוכנית בינוי פז ומרקורי-נספח תנועה
A30: 46384 | B30: א | C30: 3 | D30: רש"ת | E30: סגירת פרוטוקול לאחר קבלת תוכניות סופיות מעודכנות וארכוב ושליחה לחתימות -וועדת תנועה 11/25
C31: 4 | D31: רש"ת | E31: דיון סיור והצגת התוכניות עם המתכננים ומנהלי הפרויקט בנושא גדר חייץ למקטע 4 שלב א- הסדרי תנועה זמניים לקראת ועדת תנועה 02-26
A32: 46385 | B32: ב | C32: 3 | D32: משרד | E32: קבלת תוכניות מעודכנות ובדיקת מחלף נתב"ג מערב שלב A1-הסדרי תנועה זמניים לקראת ועדת תנועה 01/26
A33: 46386 | B33: ג | C33: 3 | D33: משרד | E33: ביצוע בקרת איכות לתוכניות +הכנת סדר יום והפצתו לחברי הועדה במייל לקראת ועדת התנועה 01/26
C34: 2 | D34: משרד | E34: מתן מענה סופי כולל פרוטוקול חתום+תוכניות לעו"ד נטלי בן
A35: סה"כ | C35: =SUM(C11:C34) -> 72 | D35: =+'נובמבר 2025 '!E43 -> 975 | E35: =D35-C35 -> 903
A38: סה"כ שעות עבודה | D38: 72
A39: מחיר לשעת עבודה
A40: סה"כ לחשבון
A41: מע"מ 18%
A42: סה"כ לחשבון | D42: =D41+D40 -> 0
A44: הצהרת העובד - הנני מצהיר בזה, כי כל הפרטים לגבי ביצוע שעות העבודה בדו"ח זה הינם נכונים ותואמים את הרישומים של משרדנו
A45: חתימה | G45: תאריך | H45: 46022
A46: שם העובד | D46: אהובה אליה
A47: אישור המתכנן | G47: אישור העיריה
...

Sheet ינואר 2026
A2: רשות שדות התעופה
A4: דוח ביצוע שעות עבודה ינואר 2026
A5: אהובה אליה-הנדסת תנועה ותחבורה | B5: כתובת :האורן 44 רמת ישי ת.ד. 1051 | C5: פלאפון: 054-9983894 | E5: עוסק מורשה: 057085250
A6: לקוח | B6: תדם | C6: 46023 | E6: רשות שדות התעופה
A7: המתכנן | B7: אהובה אליה | E7: מספר ח-ן: 01012601
A10: תאריך | B10: יום השבוע | C10: סהכ שעות עבודה | D10: מיקום | E10: נושא העבודה | K10: טיפול כולל - הכנה+ טיפול בכל נושא הארכיב החתימות וההפצה
A11: 46023 | B11: ה | C11: 2 | D11: משרד | E11: דיון עם מנהל הפרוקיט ירון מנשה + מתכנן תנועה +אדם הכהן רמ"ח ציוד ושינוע-אגף שינוע+מפקח שי עמירה - בנוגע לתוכניות סופיות וזמניות יב"ר לבקשת אדם הכהן
C12: 1 | D12: משרד | E12: בדיקה ובחינה בנוגע למעברי חירום בנתב"ג מול המתכנן לבקשת מנהל חטיבת בטחון
A13: 46026 | B13: א | C13: 3 | D13: רש"ת | E13: דיון הצגה ובקרת תוכניות בנושא מסוף בגין -הסדרי תנועה זמניים
C14: 2 | D14: רש"ת | E14: הכנת הפרוטוקול ובקשה לקבלת תוכניות מעודכנות מחלף נתב"ג שלב A1 - ועדת תנועה 01/26
A15: 46027 | B15: ב | C15: 2 | D15: משרד | E15: המשך הכנת הפרוטוקול ובקשה לקבלת תוכניות מעודכנות מחלף נתב"ג שלב A1 - ועדת תנועה 01/26
C16: 3 | D16: משרד | E16: הכנה והיכרות ראשונית בנושא תוכנית בינוי למתחם משאיות תדלוק פז ומרקורי-נספח תנועה -סבב ראשון
C17: 2 | D17: משרד | E17: דרכים בנתב"ג - דיון והצגת הנושאים שוטף עם שירלי
A18: 46029 | B18: ד | C18: 3 | D18: משרד | E18: בדיקה מתן התייחסות מפורטת לנושא שינוי גבולות רשות תמרור מסוף בגין לכל הגורמים הרלוונטים
A19: 46030 | B19: ה | C19: 3 | D19: משרד | E19: דיון ובקרת איכות לתוכניות מעודכנות בנוגע לתוכניות סופיות וזמניות יב"ר לקראת ועדת תנועה 02/26 -סבב שני
A20: 46033 | B20: א | C20: 2 | D20: רש"ת | E20: דיון ותיאום הסדרי תנועה זמניים מחלף נתב"ג שלב A1 עם יועצי התנועה
C21: 3 | D21: רש"ת | E21: לימוד והיכרות עם פרויקט כביש 40 - עוקף תעשיה אוירית לקראת פורום נתב"ג
C22: 2 | D22: רש"ת | E22: הנחת קו ביוב מתחנת רכבת תעופה- הסדרי תנועה זמניים -סיור והצגת הנושא ע"י מנהל הפרויקט שמעון שטרית לקראת ועדת תנועה 02/26
A23: 46035 | B23: ג | C23: 3 | D23: משרד | E23: לימוד והיכרות עם נושאי הדיון לקראת פורום נתב"ג
C24: 3 | D24: משרד | E24: סגירת הפרוטוקול ושליחה לחתימות לאחר קבלת תוכניות סופיות מעודכנות ולאחר ביצוע בקרת איכות לנושאים בועדת תנועה 01/26
C25: 4 | D25: משרד | E25: הכנה והיכרות ראשוני כולל דיון לתוכנית הסדרי תנועה זמניים להנחת קו ביוב רכבת תעופה - מול מתכנני התנועה לקראת ועדת תנועה סבב ראשון - 02/26
A26: 46036 | B26: ד | C26: 2 | D26: משרד | E26: פורום נתב"ג
A27: 46037 | B27: ה | C27: 4 | D27: משרד | E27: תוכנית בינוי למתחם משאיות תדלוק פז ומרקורי- בקרת איכות ומתן הערות לנספח תנועה
A28: 46040 | B28: א | C28: 2 | D28: רש"ת | E28: הפצת הפרוטוקול 01/26 לחברי ועדה התנועה כולל תיוק של התוכניות
C29: 1 | D29: רש"ת | E29: ארכוב ועדות תנועה אצל אודי עם ארזה
C30: 3 | D30: רש"ת | E30: קבלת תוכנית בינוי למתחם משאיות תדלוק פז ומרקורי- דיון ובקרת איכות מול היזמים והמתכננים לנספח תנועה
C31: 2 | D31: רש"ת | E31: דיון והצגת מחלף נתב"ג מערב שלב A1 למשטרה ולבטיחות עם המנהלי הפרוקיט +מתכננים לטובת אישור פריסת הסדרי תנועה זמניים בתוך נתב"ג
A32: 46041 | B32: ב | C32: 4 | D32: משרד | E32: קבלת פרוגרמה של תוכנית הבינוי למתחם משאיות לתדלוק פז ומרקורי מהאדריכל - לימוד והיכרות עם דרישות התנועה בנספח זה
C33: 3 | D33: משרד | E33: קבלת תוכניות מעודכנות לאחר הערות רש"ת ודיון חוזר לנספח התנועה של תוכנית הבינוי למשאיות תדלוק פז ומרקורי - מול מתכנני התנועה לקראת ועדת תנועה - 02/26
A34: 46042 | B34: ג | C34: 4 | D34: משרד | E34: קבלת תוכניות מעודכנות לאחר הערות רש"ת ודיון חוזר לתוכנית הסדרי תנועה זמניים להנחת קו ביוב רכבת תעופה - מול מתכנני התנועה לקראת ועדת תנועה - 02/26
A35: 46043 | B35: ד | C35: 1 | D35: משרד | E35: הפצת הפרוטוקול 11/25 לחברי ועדה התנועה
A36: 46044 | B36: ה | C36: 3 | D36: רש"ת | E36: דיון נוסף לבקשת מירב שולר עקב אי התאמה בין נספח התנועה לתוכניות האדרכליות בנושא מכלי הסולר-נדרש מדידה מעודכנת ותיקון של התוכניות והעברה חוזרת לדיון בועדת התנועה
C37: 6 | D37: משרד | E37: איסוף בקרת איכות לתוכניות והכנת הנושאים לסדר יום ועדת תנועה 02/26
A38: 46047 | B38: א | C38: 3 | D38: רש"ת | E38: דיון וסיור בשטח עם מנהל הפרוקיט ירון מנשה +אדם הכהן רמ"ח ציוד ושינוע-אגף שינוע+מפקח שי עמירה - בנוגע לתוכניות סופיות וזמניות יב"ר לבקשת אדם הכהן
C39: 2 | D39: רש"ת | E39: הכנה והיכרות ראשונית לנספח התנועה הרחבת תשתית טרמינלית- זרוע A- תכנון סופי לקראת ועדת תנועה - 02/26
C40: 2 | D40: רש"ת | E40: היכרות עם פרויקט תחנת דלק וטיפול בבקשת גדי רפאלי בנוגע למציאת תוכניות מצב קיים והעברתם למתכננים
A41: 46048 | B41: ב | C41: 3 | D41: משרד | E41: קבלת תוכניות מעודכנות לאחר הערות רש"ת ודיון חוזר סבב שני כולל לביצוע עבודות לילה לתוכנית הסדרי תנועה זמניים להנחת קו ביוב רכבת תעופה - מול מתכנני התנועה והקבלן סבב שני לקראת ועדת תנועה - 02/26
C42: 5 | D42: משרד | E42: הכנת דוח טבלת מאזן חניה לתוכנית בינוי מתחם משאיות ותדלוק פז ומרקורי לאחר קבלת הפרוגרמה
A43: 46051 | B43: ה | C43: 5 | D43: משרד | E43: המשך איסוף וביצוע בקרת איכות לתוכניות והכנת הנושאים לסדר יום ועדת תנועה 02/26
C44: 2 | D44: משרד | E44: המשך ביצוע בקרת איכות לנספח התנועה כולל דיון בנושא הרחבת תשתית טרמינלית- זרוע A- תכנון סופי לקראת ועדת תנועה - 02/26
...

Sheet פברואר  2026 
A2: רשות שדות התעופה
A4: דוח ביצוע שעות עבודה פברואר 2026
A5: אהובה אליה-הנדסת תנועה ותחבורה | B5: כתובת :האורן 44 רמת ישי ת.ד. 1051 | C5: פלאפון: 054-9983894 | E5: עוסק מורשה: 057085250
A6: לקוח | B6: תדם | C6: 46054 | E6: רשות שדות התעופה
A7: המתכנן | B7: אהובה אליה | E7: מספר ח-ן: 01022601
A10: תאריך | B10: יום השבוע | C10: סהכ שעות עבודה | D10: מיקום | E10: נושא העבודה | K10: טיפול כולל - הכנה+ טיפול בכל נושא הארכיב החתימות וההפצה
A11: 46054 | B11: א | C11: 2 | D11: רש"ת | E11: דיון ובקרת איכות לתוכניות מעודכנות בנוגע לתוכניות פז מרקורי לקראת ועדת תנועה 02/26 -סבב שני
C12: 1 | D12: רש"ת | E12: הכנה + פגישה בנושא הארכוב עם ארזה ואודי מחלקת GIS
C13: 3 | D13: רש"ת | E13: ביצוע בקרת איכות לתוכניות + הכנת מצגת לקראת ועדת התנועה 02/26
C14: 1 | D14: רש"ת | E14: שוטף עם ארזה ושירלי בנושאים שונים
A15: 46055 | B15: ב | C15: 3 | D15: משרד | E15: קבלת תוכניות מעודכנות לאחר הערות רש"ת ודיונים חוזרים סבב שלישי כולל לביצוע עבודות לילה לתוכנית הסדרי תנועה זמניים להנחת קו ביוב רכבת תעופה - מול מתכנני התנועה והקבלן סבב שני לקראת ועדת תנועה - 02/26
C16: 2.5 | D16: משרד | E16: הכנה והיכרות ראשונית כולל דיון עם מנהלי הפרויקט בנושא ניתוח תנועתי ודרכי גישה לחניון משכרות
A17: 46056 | B17: ג | C17: 7 | D17: משרד | E17: המשך ביצוע בקרת איכות לתוכניות + הכנת מצגת לקראת ועדת התנועה 02/26
A18: 46058 | B18: ה | C18: 2 | D18: משרד | E18: דיון והצגת הנושא ע"י המתכננים בנושא אל על צילר -נספח תנועה לקראת ועדת תנועה 02/26
C19: 3 | D19: משרד | E19: קבלת תוכניות מעודכנות לנספח התנועה הרחבת תשתית טרמינלית- זרוע A- תכנון סופי ודיון לקראת ועדת תנועה - 02/26
C20: 2 | D20: משרד | E20: הכנת סדר יום סופי והפצתו לחברי הועדה לקראת ועדת התנועה 02/26
A21: 46061 | B21: א | C21: 2 | D21: רש"ת | E21: הכנה ודיון בועדת תנועה 02/26
C22: 2.5 | D22: רש"ת | E22: דיון בוועדת התנועה במחלף נתב"ג מערב שלב A1 (נושא שלא בסדר יום)- לשינוי הסדרי התנועה הזמניים לשלב זה
C23: 3 | D23: רש"ת | E23: הכנת הפרוטוקול כולל ביצוע בקרת איכות לתוכניות וועדת תנועה 02/26
A24: 46063 | B24: ג | C24: 5 | D24: משרד | E24: המשך הכנת הפרוטוקול כולל ביצוע בקרת איכות לתוכניות ושליחת הערות לתיקונים מול יועצי התנועה לאחר ועדת תנועה 02/26
C25: 2 | D25: משרד | E25: דיון ראשוני במחלף נתב"ג מערב שלב א-עם המתכננת לשינוי הסדרי התנועה הזמניים שלב A1 בהתאם לבקשת וועדת התנועה 02/26
A26: 46065 | B26: ה | C26: 4 | D26: משרד | E26: דיון ובחינה מחדש הסדרי התנועה הזמניים מחלף נתב"ג מערב שלב A1 עם המתכננים+ עירד לטובת אישור פריסת הסדרי תנועה זמניים בתוך נתב"ג
A27: 46077 | B27: ג | C27: 4 | D27: משרד | E27: המשך הכנת הפרוטוקול כולל ביצוע בקרת איכות לתוכניות ועדת תנועה 02/26 ובקשה לעדכון התוכניות מול המתכננים
A28: 46079 | B28: ה | C28: 2 | D28: משרד | E28: המשך היכרות עם פרויקט הרחבת תחנת הדלק -הסדרי תנועה וחניה כולל דיון והצגת התוכנית ע"י המתכנן
C29: 2 | D29: משרד | E29: המשך דיון מחלף נתב"ג מערב שלב A1-עם המתכננת בנוגע ליציאת/ כניסת משאיות ומסלולם בזמן עבודות .
C30: 3 | D30: משרד | E30: מכינה לפגישה עם מנהל נתב"ג בנושא תחבורה - לימוד ודיון
A31: סה"כ | C31: =SUM(C14:C30) -> 50 | D31: =+'ינואר 2026'!E45 -> 810 | E31: =D31-C31 -> 760
A34: סה"כ שעות עבודה | D34: 50
A35: מחיר לשעת עבודה
A36: סה"כ לחשבון
A37: מע"מ 18%
A38: סה"כ לחשבון | D38: =D37+D36 -> 0
A40: הצהרת העובד - הנני מצהיר בזה, כי כל הפרטים לגבי ביצוע שעות העבודה בדו"ח זה הינם נכונים ותואמים את הרישומים של משרדנו
A41: חתימה | G41: תאריך | H41: 46081
A42: שם העובד | D42: אהובה אליה
A43: אישור המתכנן | G43: אישור העיריה
A44: לגבי סווג רמת התעריף ומספר שעות העובד : | E44: שם
A45: שם | E45: תפקיד
A46: חתימה | E46: חתימה | H46: תאריך

Sheet מרץ  2026 
A2: רשות שדות התעופה
A4: דוח ביצוע שעות עבודה מרץ 2026
A5: אהובה אליה-הנדסת תנועה ותחבורה | B5: כתובת :האורן 44 רמת ישי ת.ד. 1051 | C5: פלאפון: 054-9983894 | E5: עוסק מורשה: 057085250
A6: לקוח | B6: תדם | C6: 46082 | E6: רשות שדות התעופה
A7: המתכנן | B7: אהובה אליה | E7: מספר ח-ן: 01032601
A10: תאריך | B10: יום השבוע | C10: סהכ שעות עבודה | D10: מיקום | E10: נושא העבודה | K10: טיפול כולל - הכנה+ טיפול בכל נושא הארכיב החתימות וההפצה
A11: 46086 | B11: ה | C11: 3 | D11: משרד | E11: התייעצות ובחינה מחדש עם מתכנן התנועה הסדרי תנועה זמניים מחלף נתב"ג מערב שלב A1 - ובחינת חלופות נוספות לכניסת/ יציאת משאיות מאתרי העבודה
C12: 2 | D12: משרד | E12: שליחת חומרים לארכוב לאחר בקרת איכות לתוכניות- וועדת תנועה 02/26
C13: 2 | D13: משרד | E13: בקרת איכות לתוכנית המוצעת למחלף נתב"ג מערב A1 והעברת בקשה להתייחסותם של חברי הועדה בנוגע לחלופה המוצעת
A14: 46089 | B14: א | C14: 2 | D14: משרד | E14: מחלף נתב"ג מערב שלב A1 - המשך התייעצות עם חברי הועדה ובקשה לדיון מחדש בנוגע להסדרי התנועה הזמניים המוצעים
C15: 2 | D15: משרד | E15: קבלת תוכניות מעודכנות וביצוע בקרת איכות לנספח התנועה מיקום צ'ילר אל על ועדת תנועה - 02/26
A16: 46090 | B16: ב | C16: 2 | D16: משרד | E16: דיון ובקרת איכות לתוכניות תחנת תדלוק נתב"ג - הסדרי תנועה וחניה סבב שני
A17: 46091 | B17: ג | C17: 2 | D17: משרד | E17: טיפול ומסירת פרוטולים+תוכניות לבקשת חוק חופש המידע בנושא רמזור UPS
A18: 46092 | B18: ד | C18: 3 | D18: משרד | E18: הכנה לימוד והיכרות ראשונית כולל דיון בנושא : גדר חי"ץ תע"א -רש"ת - הסדרי תנועה זמניים מקטע 4
A19: 46100 | B19: ה | C19: 3 | D19: משרד | E19: הכנה לימוד והיכרות ראשונית לקראת דיון בנושא : מחלף נתב"ג מערב הסדרי תנועה זמניים MLR+ שלב ב
A20: 46103 | B20: א | C20: 2 | D20: משרד | E20: בקרה לתוכניות ודיון רב משתתפים בנושא : מחלף נתב"ג מערב- הסדרי תנועה זמניים לשלבי ביצוע MLR + שלב ב
C21: 2 | D21: משרד | E21: קבלת תוכניות מעודכנות וביצוע בקרת איכות כולל דיון בנושא : גדר חי"ץ תע"א -רש"ת - הסדרי תנועה זמניים מקטע 4
A22: 46104 | B22: ב | C22: 4 | D22: משרד | E22: קבלת סיכום דיון + סקיצה לנסיעת משאיות דרך MLR נתב"ג לאחר דיון בנושא : מחלף נתב"ג מערב הסדרי תנועה זמניים MLR+ שלב ב
A23: 46111 | B23: ב | C23: 2 | D23: משרד | E23: הכנה לימוד והיכרות ראשונית בנושא : הרחבות טרמינל קרקעי מזרחי
C24: 1 | D24: משרד | E24: בקשה לאיתור כולל דיון לתוכניות ופרוטוקולים לחניונים מול עו"ד לימור ט'נצר
A25: סה"כ | C25: =SUM(C11:C24) -> 32 | D25: =+'פברואר 2026 '!E31 -> 760 | E25: =D25-C25 -> 728
A28: סה"כ שעות עבודה | D28: 32
A29: מחיר לשעת עבודה
A30: סה"כ לחשבון
A31: מע"מ 18%
A32: סה"כ לחשבון | D32: =D31+D30 -> 0
A34: הצהרת העובד - הנני מצהיר בזה, כי כל הפרטים לגבי ביצוע שעות העבודה בדו"ח זה הינם נכונים ותואמים את הרישומים של משרדנו
A35: חתימה | G35: תאריך | H35: 46112
A36: שם העובד | D36: אהובה אליה
A37: אישור המתכנן | G37: אישור העיריה
A38: לגבי סווג רמת התעריף ומספר שעות העובד : | E38: שם
A39: שם | E39: תפקיד
A40: חתימה | E40: חתימה | H40: תאריך

Sheet  אפריל 2026 
A2: רשות שדות התעופה
A4: דוח ביצוע שעות עבודה אפריל 2026
A5: אהובה אליה-הנדסת תנועה ותחבורה | B5: כתובת :האורן 44 רמת ישי ת.ד. 1051 | C5: פלאפון: 054-9983894 | E5: עוסק מורשה: 057085250
A6: לקוח | B6: תדם | C6: 46113 | E6: רשות שדות התעופה
A7: המתכנן | B7: אהובה אליה | E7: מספר ח-ן: 01042601
A10: תאריך | B10: יום השבוע | C10: סהכ שעות עבודה | D10: מיקום | E10: נושא העבודה | K10: טיפול כולל - הכנה+ טיפול בכל נושא הארכיב החתימות וההפצה
A11: 46117 | B11: א | C11: 2 | D11: משרד | E11: פניה מחודשת התייעצות ודיון מחדש בשל הצורך בעדכון התוכניות בנוגע להסדרי תנועה תמרור וסימון מכלי סולר ברחבי נתב"ג לטובת היתרים- סבב נוסף - לקראת ועדת תנועה 03/26
C12: 1 | D12: משרד | E12: הכנת סדר יום לועדת תנועה 03/26
A13: 46118 | B13: ב | C13: 2 | D13: משרד | E13: קבלת תוכניות מעודכנות מתן התייחסות וסגירת סדר היום לועדת תנועה 03/26
A14: 46124 | B14: א | C14: 3 | D14: רש"ת | E14: ביצוע בקרת איכות לתוכניות +הכנת סדר יום והפצתו לחברי הועדה במייל לקראת ועדת התנועה 03/26
C15: 3.5 | D15: רש"ת | E15: מחלף נתב"ג מערב שלב A1 - קבלת תוכניות מעודכנות בחינה ובדיקת ההסדרים לקראת דיון לביצוע פירוק המדרכה והסדרת מסלול יציאה למשאיות -שלב מקדים ל - A1
A16: 46125 | B16: ב | C16: 3 | D16: משרד | E16: הכנת הפרוטוקול כולל ביצוע בקרת איכות לתוכניות ושליחה תוכניות לארכוב לועדת תנועה 03/26
C17: 2.5 | D17: משרד | E17: הכנה והיכרות ראשונית נספח התנועה הרחבה מזרחית- תכנון הסדרי תנועה זמניים מפלס G לקראת ועדת תנועה - 04/26
C18: 2 | D18: משרד | E18: מחלף נתב"ג מערב שלב A1 - דיון עם מתכנן התנועה בנוגע להסדרי התנועה הזמניים לביצוע פירוק המדרכה והסדרת מסלול יציאה למשאיות -שלב מקדים ל - A1
A19: 46126 | B19: ג | C19: 2 | D19: משרד | E19: מתן מענה סופי כולל מסירת פרוטוקול חתום+תוכניות לעו"ד לימור טנצ'ר - תובעת רשותית
C20: 2 | D20: משרד | E20: דיון עם המתכננים והמנהלי הפרויקט בנוגע לנספח התנועה הרחבה מזרחית-תוכנית הסדרי תנועה זמניים לקראת ועדת תנועה - 04/26
C21: 3 | D21: משרד | E21: מחלף נתב"ג מערב שלב A1 - קבלת תוכניות מעודכנות לאחר ישיבת התייעצות מול גורמים הרלוונטים ברשות בנוגע הסדרי תנועה זמניים שלב A1.
A22: 46128 | B22: ה | C22: 3 | D22: משרד | E22: קבלת תוכניות מעודכנות סופיות ביצוע בקרת איכות ועדת תנועה 02/26 ושליחה לארכוב
C23: 3 | D23: משרד | E23: הכנה והיכרות ראשונית חניון בנין ראשי ישן (מושכרות)- תכנון הסדרי תנועה וחניה כולל דיון עם מתכנני התנועה ומנהלי הפרויקט
A24: 46131 | B24: א | C24: 4 | D24: משרד | E24: הכנה והיכרות ראשונית כולל דיון רב משתתפים בנושא : מחלף נתב"ג מערב- הצגת עקרונות להסדרי תנועה זמניים שלב ב
A25: 46132 | B25: ב | C25: 2 | D25: רש"ת | E25: לימוד הכנה נושאי תנועה לקראת דיון כולל דיון בלשכת המנכ"ל נתב"ג
C26: 2.5 | D26: רש"ת | E26: קבלת תוכניות מעודכנות סופיות ביצוע בקרת איכות ועדת תנועה 03/26 ושליחה לארכוב
C27: 3 | D27: רש"ת | E27: קבלת תוכניות מעודכנות סופיות ביצוע בקרת איכות ועדת תנועה 02/26 ושליחה לארכוב
A28: 46133 | B28: ג | C28: 2 | D28: משרד | E28: סגירת פרוטוקול 03/26 ושליחת תוכניות סופיות להעתקות
C29: 2 | D29: משרד | E29: סגירת פרוטוקול 02/26 ושליחת תוכניות סופיות להעתקות
C30: 2 | D30: משרד | E30: ביצוע בקרת איכות לתוכניות +הכנת סדר יום והפצתו לחברי הועדה במייל לקראת ועדת התנועה 04/26
A31: 46135 | B31: ה | C31: 1 | D31: משרד | E31: הצגת תוכניות הסדרי התנועה הזמניים לביצוע כולל עבודות לילה -הנחת קו ביוב רכבת תעופה - תיאום מול הקבלן + המשטרה
C32: 6 | D32: משרד | E32: קבלת תוכניות מעודכנות + סגירת סדר יום סופי + והכנת מצגת לועדת תנועה 04/26
A33: 46138 | B33: א | C33: 2 | D33: רש"ת | E33: הכנה ודיון בועדת תנועה 04/26
C34: 2 | D34: רש"ת | E34: קבלת תוכניות והיכרות ראשונית עם תוכנית הבינוי -מבנה אנרגיה נתב"ג - נספח התנועה
C35: 3 | D35: רש"ת | E35: הכנה ולמידת נושאים לקראת פורום נתב"ג
A36: 46141 | B36: ד | C36: 2 | D36: משרד | E36: פורום נתב"ג - דיון
A37: 46142 | B37: ה | C37: 3.5 | D37: משרד | E37: הכנת הפרוטוקול כולל ביצוע בקרת איכות לתוכניות ועדת תנועה 04/26 ובקשה לעדכון התוכניות מול המתכננים
C38: 3 | D38: משרד | E38: מחלף נתב"ג מערב שלב A1 - קבלת תוכניות מעודכנות בחינה ובדיקת ההסדרים למסלול שלבים A0 וA1 כולל דיון מול מנהלי הפרויקט לקבלת הבהרות
A39: סה"כ | C39: =SUM(C11:C38) -> 72 | D39: =+'מרץ 2026 '!E25 -> 728 | E39: =D39-C39 -> 656
A42: סה"כ שעות עבודה | D42: 72
A43: מחיר לשעת עבודה
A44: סה"כ לחשבון
A45: מע"מ 18%
A46: סה"כ לחשבון | D46: =D45+D44 -> 0
...

Sheet גיליון2
